<?xml version="1.0" encoding="UTF-8"?>
<testng-results skipped="0" failed="1" total="1" passed="0">
  <reporter-output>
  </reporter-output>
  <suite name="Default suite" duration-ms="4168" started-at="2018-07-12T04:40:37Z" finished-at="2018-07-12T04:40:41Z">
    <groups>
    </groups>
    <test name="Default test" duration-ms="4168" started-at="2018-07-12T04:40:37Z" finished-at="2018-07-12T04:40:41Z">
      <class name="testLink.TestClass">
        <test-method status="PASS" signature="launch()[pri:0, instance:testLink.TestClass@cc285f4]" name="launch" is-config="true" duration-ms="2607" started-at="2018-07-12T10:10:37Z" finished-at="2018-07-12T10:10:40Z">
          <reporter-output>
          </reporter-output>
        </test-method> <!-- launch -->
        <test-method status="FAIL" signature="test001_basic_auth_test()[pri:0, instance:testLink.TestClass@cc285f4]" name="test001_basic_auth_test" duration-ms="1547" started-at="2018-07-12T10:10:40Z" finished-at="2018-07-12T10:10:41Z">
          <exception class="java.lang.AssertionError">
            <message>
              <![CDATA[expected [Congratulations! You must have the proper credentials.] but found [ss]]]>
            </message>
            <full-stacktrace>
              <![CDATA[java.lang.AssertionError: expected [Congratulations! You must have the proper credentials.] but found [ss]
	at org.testng.Assert.fail(Assert.java:94)
	at org.testng.Assert.failNotEquals(Assert.java:494)
	at org.testng.Assert.assertEquals(Assert.java:123)
	at org.testng.Assert.assertEquals(Assert.java:176)
	at org.testng.Assert.assertEquals(Assert.java:186)
	at testLink.TestClass.test001_basic_auth_test(TestClass.java:24)
	at sun.reflect.NativeMethodAccessorImpl.invoke0(Native Method)
	at sun.reflect.NativeMethodAccessorImpl.invoke(NativeMethodAccessorImpl.java:62)
	at sun.reflect.DelegatingMethodAccessorImpl.invoke(DelegatingMethodAccessorImpl.java:43)
	at java.lang.reflect.Method.invoke(Method.java:498)
	at org.testng.internal.MethodInvocationHelper.invokeMethod(MethodInvocationHelper.java:80)
	at org.testng.internal.Invoker.invokeMethod(Invoker.java:714)
	at org.testng.internal.Invoker.invokeTestMethod(Invoker.java:901)
	at org.testng.internal.Invoker.invokeTestMethods(Invoker.java:1231)
	at org.testng.internal.TestMethodWorker.invokeTestMethods(TestMethodWorker.java:127)
	at org.testng.internal.TestMethodWorker.run(TestMethodWorker.java:111)
	at org.testng.TestRunner.privateRun(TestRunner.java:767)
	at org.testng.TestRunner.run(TestRunner.java:617)
	at org.testng.SuiteRunner.runTest(SuiteRunner.java:334)
	at org.testng.SuiteRunner.runSequentially(SuiteRunner.java:329)
	at org.testng.SuiteRunner.privateRun(SuiteRunner.java:291)
	at org.testng.SuiteRunner.run(SuiteRunner.java:240)
	at org.testng.SuiteRunnerWorker.runSuite(SuiteRunnerWorker.java:52)
	at org.testng.SuiteRunnerWorker.run(SuiteRunnerWorker.java:86)
	at org.testng.TestNG.runSuitesSequentially(TestNG.java:1198)
	at org.testng.TestNG.runSuitesLocally(TestNG.java:1123)
	at org.testng.TestNG.run(TestNG.java:1031)
	at org.testng.remote.AbstractRemoteTestNG.run(AbstractRemoteTestNG.java:114)
	at org.testng.remote.RemoteTestNG.initAndRun(RemoteTestNG.java:251)
	at org.testng.remote.RemoteTestNG.main(RemoteTestNG.java:77)
]]>
            </full-stacktrace>
          </exception> <!-- java.lang.AssertionError -->
          <reporter-output>
          </reporter-output>
        </test-method> <!-- test001_basic_auth_test -->
      </class> <!-- testLink.TestClass -->
    </test> <!-- Default test -->
  </suite> <!-- Default suite -->
</testng-results>
